<?xml version='1.0'?>
    <sdf version='1.4'>
        <model name="my_robot">
            <static>false</static>
        <link name='chassis'>
          <pose>0 0 .1 0 0 0</pose>
          <collision name='collision'>
            <geometry>
              <box>
                <size>.4 .2 .1</size>
              </box>
            </geometry>
          </collision>

          <visual name='visual'>
            <pose>0 0 0.05 0 0 0</pose>
            <geometry>
                <mesh>
                    <uri>model://pioneer2dx/meshes/chassis.dae</uri>
                    <scale>0.9 0.5 0.5</scale>
                </mesh>
            </geometry>
          </visual>

          <collision name='caster_collision'>
            <pose>-0.15 0 -0.05 0 0 0</pose>
            <geometry>
              <sphere>
              <radius>.05</radius>
            </sphere>
          </geometry>

          <surface>
            <friction>
              <ode>
                <mu>0</mu>
                <mu2>0</mu2>
                <slip1>1.0</slip1>
                <slip2>1.0</slip2>
              </ode>
            </friction>
          </surface>
        </collision>

        <visual name='caster_visual'>
          <pose>-0.15 0 -0.05 0 0 0</pose>
          <geometry>
            <sphere>
              <radius>.05</radius>
            </sphere>
          </geometry>
        </visual>
      </link>
      <link name="left_wheel">
        <pose>0.1 0.13 0.1 0 1.5707 1.5707</pose>
        <collision name="collision">
          <geometry>
            <cylinder>
              <radius>.1</radius>
              <length>.05</length>
            </cylinder>
          </geometry>
        </collision>
        <visual name="visual">
          <geometry>
            <cylinder>
              <radius>.1</radius>
              <length>.05</length>
            </cylinder>
          </geometry>
        </visual>
      </link>

      <link name="right_wheel">
        <pose>0.1 -0.13 0.1 0 1.5707 1.5707</pose>
        <collision name="collision">
          <geometry>
            <cylinder>
              <radius>.1</radius>
              <length>.05</length>
            </cylinder>
          </geometry>
        </collision>
        <visual name="visual">
          <geometry>
            <cylinder>
              <radius>.1</radius>
              <length>.05</length>
            </cylinder>
          </geometry>
        </visual>
      </link>
      <joint type="revolute" name="left_wheel_hinge">
        <pose>0 0 -0.03 0 0 0</pose>
        <child>left_wheel</child>
        <parent>chassis</parent>
        <axis>
          <xyz>0 1 0</xyz>
        </axis>
      </joint>

      <joint type="revolute" name="right_wheel_hinge">
        <pose>0 0 0.03 0 0 0</pose>
        <child>right_wheel</child>
        <parent>chassis</parent>
        <axis>
          <xyz>0 1 0</xyz>
        </axis>
      </joint>
      <!--hokuyo,velodyne_hdl32-->
      <!-- <include>
        <uri>model://velodyne_hdl32</uri> 
        <pose>0.2 0 5.2 0 0 0</pose>
        </include>
        <joint name="velodyne_hdl32_joint" type="fixed">
            
            <child>velodyne::base</child>
            <parent>chassis</parent>
        </joint> -->
        
        <model name='velodyne'>
            <link name='base'>
                <pose frame=''>0 0 0.03 0 -0 0</pose>
                <inertial>
                <mass>0.1</mass>
                <inertia>
                    <ixx>0.00108747</ixx>
                    <iyy>0.00108747</iyy>
                    <izz>0.00109244</izz>
                    <ixy>0</ixy>
                    <ixz>0</ixz>
                    <iyz>0</iyz>
                </inertia>
                </inertial>
                <collision name='base_collision'>
                <geometry>
                    <cylinder>
                    <radius>0.04267</radius>
                    <length>0.05867</length>
                    </cylinder>
                </geometry>
                </collision>
                <visual name='base_visual'>
                <pose frame=''>0 0 -0.029335 0 -0 0</pose>
                <geometry>
                    <mesh>
                    <uri>model://velodyne_hdl32/meshes/velodyne_base.dae</uri>
                    </mesh>
                </geometry>
                </visual>
            </link>
            <link name='top'>
                <pose frame=''>0 0 0.095455 0 -0 0</pose>
                <inertial>
                <mass>0.1</mass>
                <inertia>
                    <ixx>9.0623e-05</ixx>
                    <iyy>9.0623e-05</iyy>
                    <izz>9.1036e-05</izz>
                    <ixy>0</ixy>
                    <ixz>0</ixz>
                    <iyz>0</iyz>
                </inertia>
                </inertial>
                <collision name='top_collision'>
                <geometry>
                    <cylinder>
                    <radius>0.04267</radius>
                    <length>0.07357</length>
                    </cylinder>
                </geometry>
                </collision>
                <visual name='top_visual'>
                <pose frame=''>0 0 -0.037679 0 -0 1.5707</pose>
                <geometry>
                    <mesh>
                    <uri>model://velodyne_hdl32/meshes/velodyne_top.dae</uri>
                    </mesh>
                </geometry>
                </visual>
                <sensor name='HDL-32E-HDL32E' type='ray'>
                <pose frame=''>0 0 -0.004645 1.5707 -0 0</pose>
                <visualize>0</visualize>
                <update_rate>30</update_rate>
                <ray>
                    <noise>
                    <type>gaussian</type>
                    <mean>0</mean>
                    <stddev>0.1</stddev>
                    </noise>
                    <scan>
                    <horizontal>
                        <samples>32</samples>
                        <resolution>2187</resolution>
                        <min_angle>-3.1415926535897931</min_angle>
                        <max_angle>3.1415926535897931</max_angle>
                    </horizontal>
                    </scan>
                    <range>
                    <min>0.1</min>
                    <max>70</max>
                    <resolution>0.02</resolution>
                    </range>
                </ray>
                </sensor>
            </link>
            <joint name='velodyne-joint' type='revolute'>
                <pose frame=''>0 0 -0.036785 0 -0 0</pose>
                <parent>base</parent>
                <child>top</child>
                <axis>
                <xyz>0 0 1</xyz>
                <limit>
                    <lower>-1e+16</lower>
                    <upper>1e+16</upper>
                </limit>
                <use_parent_model_frame>0</use_parent_model_frame>
                </axis>
            </joint>
                <!-- <static>0</static> -->
                <!--<pose frame=''>0.2 0 0.2 0 0 0</pose>-->
            <pose>0.2 0 6.2 0 0 0</pose>
        </model>
        <joint name='velodyne-to-base-joint' type='fixed'>
            <child>velodyne::base</child>
            <parent>chassis</parent>
        </joint>
       
    </model>

</sdf>